<?xml version="1.0"?>
<robot name="robot" xmlns:xacro="http://www.ros.org/wiki/xacro">

    <!-- Material Definitions -->
    <material name="white">
        <color rgba="1 1 1 1"/>
    </material>

    <material name="gray">
        <color rgba="0.5 0.5 0.5 1"/>
    </material>

    <material name="black">
        <color rgba="0 0 0 1"/>
    </material>

    <!-- Base Link -->
    <link name="base_link">
        <visual>
            <origin xyz="0.035 0 0.03"/>
            <geometry>
                <box size="0.2 0.2 0.1"/> <!-- Dimensions of the main body -->
            </geometry>
            <material name="gray"/>
        </visual>
        <collision>
            <origin xyz="0 0 0.05"/>
            <geometry>
                <box size="0.2 0.2 0.1"/>
            </geometry>
        </collision>
        <inertial>
            <mass value="0.5"/>
            <origin xyz="0 0 0.05"/>
            <inertia ixx="0.01" ixy="0" ixz="0" iyy="0.01" iyz="0" izz="0.01"/>
        </inertial>
    </link>

    <!-- Right Wheel -->
    <joint name="right_wheel_joint" type="continuous">
        <parent link="base_link"/>
        <child link="right_wheel"/>
        <origin xyz="0 -0.1 0" rpy="-${pi/2} 0 0"/>
        <axis xyz="0 0 1"/>
    </joint>

    <link name="right_wheel">
        <visual>
            <origin xyz="0 0 0" rpy="0 0 0"/>
            <geometry>
                <cylinder radius="0.06" length="0.02"/> <!-- 120 mm diameter -->
            </geometry>
            <material name="black"/>
        </visual>
        <collision>
            <origin xyz="0 0 0" rpy="0 0 0"/>
            <geometry>
                <cylinder radius="0.06" length="0.02"/>
            </geometry>
        </collision>
        <inertial>
            <mass value="0.1"/>
            <origin xyz="0 0 0"/>
            <inertia ixx="0.001" ixy="0" ixz="0" iyy="0.001" iyz="0" izz="0.001"/>
        </inertial>
    </link>

    <!-- Left Wheel -->
    <joint name="left_wheel_joint" type="continuous">
        <parent link="base_link"/>
        <child link="left_wheel"/>
        <origin xyz="0 0.1 0" rpy="${pi/2} 0 0"/>
        <axis xyz="0 0 1"/>
    </joint>

    <link name="left_wheel">
        <visual>
            <origin xyz="0 0 0" rpy="0 0 0"/>
            <geometry>
                <cylinder radius="0.06" length="0.02"/> <!-- 120 mm diameter -->
            </geometry>
            <material name="black"/>
        </visual>
        <collision>
            <origin xyz="0 0 0" rpy="0 0 0"/>
            <geometry>
                <cylinder radius="0.06" length="0.02"/>
            </geometry>
        </collision>
        <inertial>
            <mass value="0.1"/>
            <origin xyz="0 0 0"/>
            <inertia ixx="0.001" ixy="0" ixz="0" iyy="0.001" iyz="0" izz="0.001"/>
        </inertial>
    </link>

    <!-- Caster Wheel -->
    <joint name="caster_wheel_joint" type="fixed">
        <parent link="base_link"/>
        <child link="caster_wheel"/>
        <origin xyz="0.061 0 -0.035"/>
    </joint>

    <link name="caster_wheel">
        <visual>
            <geometry>
                <sphere radius="0.021"/> <!-- 42 mm diameter -->
            </geometry>
            <material name="black"/>
        </visual>
        <collision>
            <geometry>
                <sphere radius="0.021"/>
            </geometry>
        </collision>
        <inertial>
            <mass value="0.05"/>
            <origin xyz="0 0 0"/>
            <inertia ixx="0.0001" ixy="0" ixz="0" iyy="0.0001" iyz="0" izz="0.0001"/>
        </inertial>
    </link>

    <!-- Lidar Sensor -->
    <link name="lidar_link">
        <visual>
            <geometry>
                <cylinder radius="0.03" length="0.02"/> <!-- Lidar body -->
            </geometry>
            <material name="black"/>
        </visual>
        <collision>
            <geometry>
                <cylinder radius="0.03" length="0.02"/>
            </geometry>
        </collision>
        <origin xyz="0 0 0.15"/>
    </link>

    <joint name="lidar_joint" type="fixed">
        <parent link="base_link"/>
        <child link="lidar_link"/>
        <origin xyz="0.1 0 0.09"/>
    </joint>

    <gazebo>
        <sensor type="gpu_ray" name="laser_sensor">
            <pose>0 0 0.15 0 0 0</pose>
            <visualize>true</visualize>
            <update_rate>30</update_rate>
            <ray>
                <scan>
                    <horizontal>
                        <samples>720</samples>
                        <resolution>1</resolution>
                        <min_angle>-1.5708</min_angle>
                        <max_angle>1.5708</max_angle>
                    </horizontal>
                </scan>
                <range>
                    <min>0.05</min>
                    <max>10.0</max>
                </range>
            </ray>
            <plugin name="gazebo_ros_laser" filename="libgazebo_ros_laser.so">
                <robotNamespace/>
                <topicName>scan</topicName>
            </plugin>
        </sensor>
    </gazebo>

    <!-- RGB Camera -->
    <link name="camera_link">
        <visual>
            <geometry>
                <box size="0.05 0.05 0.05"/> <!-- Camera dimensions -->
            </geometry>
            <material name="black"/>
        </visual>
        <collision>
            <geometry>
                <box size="0.01 0.01 0.01"/>
            </geometry>
        </collision>
        <origin xyz="0 0 0.2"/>
    </link>

    <joint name="camera_joint" type="fixed">
        <parent link="base_link"/>
        <child link="camera_link"/>
        <origin xyz="0.14 0 0.03" rpy="0 0 0"/>
    </joint>

    <gazebo>
        <sensor type="camera" name="camera_sensor">
            <camera>
                <horizontal_fov>1.3962634</horizontal_fov>
                <image>
                    <width>640</width>
                    <height>480</height>
                    <format>R8G8B8</format>
                </image>
                <clip>
                    <near>0.1</near>
                    <far>100.0</far>
                </clip>
            </camera>
            <plugin name="gazebo_ros_camera" filename="libgazebo_ros_camera.so">
                <robotNamespace/>
                <alwaysOn>true</alwaysOn>
                <updateRate>30.0</updateRate>
                <cameraName>camera</cameraName>
                <imageTopicName>camera/image_raw</imageTopicName>
            </plugin>
        </sensor>
    </gazebo>

    <!-- Differential Drive System -->
    <gazebo>
        <plugin name="gazebo_ros_control" filename="libgazebo_ros_control.so"/>
    </gazebo>

    <gazebo>
        <plugin name="differential_drive_controller" filename="libgazebo_ros_diff_drive.so">
            <robotNamespace/>
            <updateRate>100</updateRate>
            <leftJoint>left_wheel_joint</leftJoint>
            <rightJoint>right_wheel_joint</rightJoint>
            <wheelSeparation>0.2</wheelSeparation> <!-- Adjust as needed -->
            <wheelDiameter>0.12</wheelDiameter> <!-- Adjust as needed -->
            <torque>5.0</torque>
            <commandTopic>cmd_vel</commandTopic>
            <odometryTopic>odom</odometryTopic>
            <odometryFrame>odom</odometryFrame>
            <robotBaseFrame>base_link</robotBaseFrame>
            <publishOdom>true</publishOdom>
        </plugin>
    </gazebo>
</robot>
